Workbook

Sheet Theo_doi_don_nghi
A1: SỔ THEO DÕI NGHỈ PHÉP & NGHỈ VIỆC RIÊNG NĂM 2026 - CÔNG TY A
A2: Hệ thống quản lý chấm công & phép | Dữ liệu cập nhật: Năm 2026
A4: Mã đơn | B4: Mã NV | C4: Họ và tên | D4: Phòng ban | E4: Loại nghỉ phép | F4: Từ ngày | G4: Đến ngày | H4: Số ngày | I4: Lý do xin nghỉ | J4: Người phê duyệt | K4: Trạng thái duyệt
A5: NP-2026-0012 | B5: TP0003 | C5: Trần Mai Phương | D5: Ban Giám đốc | E5: Nghỉ phép năm | F5: 2026-01-22 | G5: 2026-01-23 | H5: 2 | I5: Giải quyết việc cá nhân gia đình | J5: Phạm Thái Hùng | K5: Đã duyệt
A6: NP-2026-0045 | B6: TP0010 | C6: Nguyễn Bích Thủy | D6: Phòng Tài chính - Kế toán | E6: Nghỉ phép năm | F6: 2026-02-19 | G6: 2026-02-20 | H6: 2 | I6: Về quê ăn giỗ | J6: Lê Thu Lan | K6: Đã duyệt
A7: NP-2026-0088 | B7: TP0018 | C7: Phạm Quốc Bảo | D7: Phòng Kinh doanh & Marketing | E7: Nghỉ ốm đau ngắn ngày | F7: 2026-03-11 | G7: 2026-03-13 | H7: 3 | I7: Sốt xuất huyết, điều trị ngoại trú có GCN BHXH | J7: Nguyễn Văn Hùng | K7: Đã duyệt
A8: NP-2026-0115 | B8: TP0027 | C8: Vũ Đình Bách | D8: Phòng Kỹ thuật & Công nghệ | E8: Nghỉ chế độ việc riêng có lương | F8: 2026-03-25 | G8: 2026-03-27 | H8: 3 | I8: Kết hôn cá nhân (hưởng nguyên lương theo luật) | J8: Đỗ Trọng Thắng | K8: Đã duyệt
A9: NP-2026-0142 | B9: TP0034 | C9: Trần Văn Bình | D9: Xưởng Sản xuất & Vận hành | E9: Nghỉ phép năm | F9: 2026-04-14 | G9: 2026-04-15 | H9: 2 | I9: Việc gia đình | J9: Nguyễn Khắc Quyền | K9: Đã duyệt
A10: NP-2026-0180 | B10: TP0046 | C10: Nguyễn Thị Sen | D10: Xưởng Sản xuất & Vận hành | E10: Nghỉ thai sản | F10: 2026-05-01 | G10: 2026-10-31 | H10: 156 | I10: Nghỉ sinh con theo chế độ thai sản BHXH 6 tháng | J10: Nguyễn Khắc Quyền | K10: Đã duyệt
A11: NP-2026-0210 | B11: TP0005 | C11: Đỗ Thị Quỳnh Nga | D11: Phòng Hành chính - Nhân sự | E11: Nghỉ phép năm | F11: 2026-06-08 | G11: 2026-06-09 | H11: 2 | I11: Du lịch nghỉ hè cùng gia đình | J11: Hà Quang Dũng | K11: Đã duyệt
A12: NP-2026-0245 | B12: TP0016 | C12: Đặng Minh Nam | D12: Phòng Kinh doanh & Marketing | E12: Nghỉ phép năm | F12: 2026-06-22 | G12: 2026-06-23 | H12: 2 | I12: Nghỉ phép thường niên | J12: Nguyễn Văn Hùng | K12: Đã duyệt
A13: NP-2026-0298 | B13: TP0007 | C13: Nguyễn Ngọc Bích | D13: Phòng Hành chính - Nhân sự | E13: Nghỉ phép năm | F13: 2026-07-06 | G13: 2026-07-06 | H13: 1 | I13: Khám sức khỏe tổng quát | J13: Hà Quang Dũng | K13: Đã duyệt
A14: NP-2026-0312 | B14: TP0020 | C14: Vũ Hoàng Long | D14: Phòng Kinh doanh & Marketing | E14: Nghỉ không lương | F14: 2026-07-15 | G14: 2026-07-16 | H14: 2 | I14: Giải quyết việc đột xuất ở quê | J14: Nguyễn Văn Hùng | K14: Đã duyệt
A15: NP-2026-0330 | B15: TP0038 | C15: Lương Ngọc An | D15: Xưởng Sản xuất & Vận hành | E15: Nghỉ phép năm | F15: 2026-07-20 | G15: 2026-07-21 | H15: 2 | I15: Nghỉ giải quyết việc gia đình | J15: Nguyễn Khắc Quyền | K15: Đã duyệt
A16: NP-2026-0355 | B16: TP0041 | C16: Bùi Quang Lãm | D16: Xưởng Sản xuất & Vận hành | E16: Nghỉ ốm đau ngắn ngày | F16: 2026-07-27 | G16: 2026-07-28 | H16: 2 | I16: Nhiễm siêu vi, điều trị tại nhà | J16: Nguyễn Khắc Quyền | K16: Đã duyệt
... A28: NP-2026-0520 | B28: TP0040 | C28: Nguyễn Văn Minh | D28: Xưởng Sản xuất & Vận hành | E28: Nghỉ không lương | F28: 2026-10-08 | G28: 2026-10-09 | H28: 2 | I28: Việc gia đình ở quê Phú Thọ | J28: Nguyễn Khắc Quyền | K28: Chờ duyệt

Sheet Quy_phep_nam
A1: BẢNG TỔNG HỢP QUỸ PHÉP NĂM 2026 CỦA NHÂN VIÊN
A3: Mã NV | B3: Họ và tên | C3: Phòng ban | D3: Phép tiêu chuẩn | E3: Phép thâm niên | F3: Tổng quỹ phép 2026 | G3: Đã sử dụng | H3: Còn lại | I3: Ghi chú
A4: TP0001 | B4: Phạm Thái Hùng | C4: Ban Giám đốc | D4: 12 | E4: 1 | F4: =D4+E4 | G4: =SUMIFS(Theo_doi_don_nghi!H5:H28, Theo_doi_don_nghi!B5:B28, "TP0001", Theo_doi_don_nghi!E5:E28, "Nghỉ phép năm", Theo_doi_don_nghi!K5:K28, "Đã duyệt") | H4: =F4-G4 | I4: Bình thường
A5: TP0002 | B5: Nguyễn Minh Tuấn | C5: Ban Giám đốc | D5: 12 | E5: 1 | F5: =D5+E5 | G5: =SUMIFS(Theo_doi_don_nghi!H5:H28, Theo_doi_don_nghi!B5:B28, "TP0002", Theo_doi_don_nghi!E5:E28, "Nghỉ phép năm", Theo_doi_don_nghi!K5:K28, "Đã duyệt") | H5: =F5-G5 | I5: Bình thường
A6: TP0003 | B6: Trần Mai Phương | C6: Ban Giám đốc | D6: 12 | E6: 0 | F6: =D6+E6 | G6: =SUMIFS(Theo_doi_don_nghi!H5:H28, Theo_doi_don_nghi!B5:B28, "TP0003", Theo_doi_don_nghi!E5:E28, "Nghỉ phép năm", Theo_doi_don_nghi!K5:K28, "Đã duyệt") | H6: =F6-G6 | I6: Bình thường
A7: TP0004 | B7: Hà Quang Dũng | C7: Phòng Hành chính - Nhân sự | D7: 12 | E7: 1 | F7: =D7+E7 | G7: =SUMIFS(Theo_doi_don_nghi!H5:H28, Theo_doi_don_nghi!B5:B28, "TP0004", Theo_doi_don_nghi!E5:E28, "Nghỉ phép năm", Theo_doi_don_nghi!K5:K28, "Đã duyệt") | H7: =F7-G7 | I7: Bình thường
A8: TP0005 | B8: Đỗ Thị Quỳnh Nga | C8: Phòng Hành chính - Nhân sự | D8: 12 | E8: 0 | F8: =D8+E8 | G8: =SUMIFS(Theo_doi_don_nghi!H5:H28, Theo_doi_don_nghi!B5:B28, "TP0005", Theo_doi_don_nghi!E5:E28, "Nghỉ phép năm", Theo_doi_don_nghi!K5:K28, "Đã duyệt") | H8: =F8-G8 | I8: Bình thường
A9: TP0006 | B9: Vũ Phương Linh | C9: Phòng Hành chính - Nhân sự | D9: 12 | E9: 0 | F9: =D9+E9 | G9: =SUMIFS(Theo_doi_don_nghi!H5:H28, Theo_doi_don_nghi!B5:B28, "TP0006", Theo_doi_don_nghi!E5:E28, "Nghỉ phép năm", Theo_doi_don_nghi!K5:K28, "Đã duyệt") | H9: =F9-G9 | I9: Bình thường
A10: TP0007 | B10: Nguyễn Ngọc Bích | C10: Phòng Hành chính - Nhân sự | D10: 12 | E10: 0 | F10: =D10+E10 | G10: =SUMIFS(Theo_doi_don_nghi!H5:H28, Theo_doi_don_nghi!B5:B28, "TP0007", Theo_doi_don_nghi!E5:E28, "Nghỉ phép năm", Theo_doi_don_nghi!K5:K28, "Đã duyệt") | H10: =F10-G10 | I10: Bình thường
A11: TP0008 | B11: Hoàng Thu Thảo | C11: Phòng Hành chính - Nhân sự | D11: 0 | E11: 0 | F11: =D11+E11 | G11: =SUMIFS(Theo_doi_don_nghi!H5:H28, Theo_doi_don_nghi!B5:B28, "TP0008", Theo_doi_don_nghi!E5:E28, "Nghỉ phép năm", Theo_doi_don_nghi!K5:K28, "Đã duyệt") | H11: =F11-G11 | I11: Đang thử việc - chưa cấp phép
A12: TP0009 | B12: Lê Thu Lan | C12: Phòng Tài chính - Kế toán | D12: 12 | E12: 1 | F12: =D12+E12 | G12: =SUMIFS(Theo_doi_don_nghi!H5:H28, Theo_doi_don_nghi!B5:B28, "TP0009", Theo_doi_don_nghi!E5:E28, "Nghỉ phép năm", Theo_doi_don_nghi!K5:K28, "Đã duyệt") | H12: =F12-G12 | I12: Bình thường
A13: TP0010 | B13: Nguyễn Bích Thủy | C13: Phòng Tài chính - Kế toán | D13: 12 | E13: 0 | F13: =D13+E13 | G13: =SUMIFS(Theo_doi_don_nghi!H5:H28, Theo_doi_don_nghi!B5:B28, "TP0010", Theo_doi_don_nghi!E5:E28, "Nghỉ phép năm", Theo_doi_don_nghi!K5:K28, "Đã duyệt") | H13: =F13-G13 | I13: Bình thường
A14: TP0011 | B14: Trần Thùy Dương | C14: Phòng Tài chính - Kế toán | D14: 12 | E14: 0 | F14: =D14+E14 | G14: =SUMIFS(Theo_doi_don_nghi!H5:H28, Theo_doi_don_nghi!B5:B28, "TP0011", Theo_doi_don_nghi!E5:E28, "Nghỉ phép năm", Theo_doi_don_nghi!K5:K28, "Đã duyệt") | H14: =F14-G14 | I14: Bình thường
A15: TP0012 | B15: Phan Thanh Hoa | C15: Phòng Tài chính - Kế toán | D15: 12 | E15: 0 | F15: =D15+E15 | G15: =SUMIFS(Theo_doi_don_nghi!H5:H28, Theo_doi_don_nghi!B5:B28, "TP0012", Theo_doi_don_nghi!E5:E28, "Nghỉ phép năm", Theo_doi_don_nghi!K5:K28, "Đã duyệt") | H15: =F15-G15 | I15: Bình thường
A16: TP0013 | B16: Bùi Văn Khôi | C16: Phòng Tài chính - Kế toán | D16: 12 | E16: 0 | F16: =D16+E16 | G16: =SUMIFS(Theo_doi_don_nghi!H5:H28, Theo_doi_don_nghi!B5:B28, "TP0013", Theo_doi_don_nghi!E5:E28, "Nghỉ phép năm", Theo_doi_don_nghi!K5:K28, "Đã duyệt") | H16: =F16-G16 | I16: Bình thường
A17: TP0014 | B17: Nguyễn Văn Hùng | C17: Phòng Kinh doanh & Marketing | D17: 12 | E17: 1 | F17: =D17+E17 | G17: =SUMIFS(Theo_doi_don_nghi!H5:H28, Theo_doi_don_nghi!B5:B28, "TP0014", Theo_doi_don_nghi!E5:E28, "Nghỉ phép năm", Theo_doi_don_nghi!K5:K28, "Đã duyệt") | H17: =F17-G17 | I17: Bình thường
A18: TP0015 | B18: Nguyễn Việt Kiên | C18: Phòng Kinh doanh & Marketing | D18: 12 | E18: 0 | F18: =D18+E18 | G18: =SUMIFS(Theo_doi_don_nghi!H5:H28, Theo_doi_don_nghi!B5:B28, "TP0015", Theo_doi_don_nghi!E5:E28, "Nghỉ phép năm", Theo_doi_don_nghi!K5:K28, "Đã duyệt") | H18: =F18-G18 | I18: Bình thường
A19: TP0016 | B19: Đặng Minh Nam | C19: Phòng Kinh doanh & Marketing | D19: 12 | E19: 0 | F19: =D19+E19 | G19: =SUMIFS(Theo_doi_don_nghi!H5:H28, Theo_doi_don_nghi!B5:B28, "TP0016", Theo_doi_don_nghi!E5:E28, "Nghỉ phép năm", Theo_doi_don_nghi!K5:K28, "Đã duyệt") | H19: =F19-G19 | I19: Bình thường
A20: TP0017 | B20: Lê Diệu Linh | C20: Phòng Kinh doanh & Marketing | D20: 12 | E20: 0 | F20: =D20+E20 | G20: =SUMIFS(Theo_doi_don_nghi!H5:H28, Theo_doi_don_nghi!B5:B28, "TP0017", Theo_doi_don_nghi!E5:E28, "Nghỉ phép năm", Theo_doi_don_nghi!K5:K28, "Đã duyệt") | H20: =F20-G20 | I20: Bình thường
A21: TP0018 | B21: Phạm Quốc Bảo | C21: Phòng Kinh doanh & Marketing | D21: 12 | E21: 0 | F21: =D21+E21 | G21: =SUMIFS(Theo_doi_don_nghi!H5:H28, Theo_doi_don_nghi!B5:B28, "TP0018", Theo_doi_don_nghi!E5:E28, "Nghỉ phép năm", Theo_doi_don_nghi!K5:K28, "Đã duyệt") | H21: =F21-G21 | I21: Bình thường
A22: TP0019 | B22: Trần Hải Yến | C22: Phòng Kinh doanh & Marketing | D22: 12 | E22: 0 | F22: =D22+E22 | G22: =SUMIFS(Theo_doi_don_nghi!H5:H28, Theo_doi_don_nghi!B5:B28, "TP0019", Theo_doi_don_nghi!E5:E28, "Nghỉ phép năm", Theo_doi_don_nghi!K5:K28, "Đã duyệt") | H22: =F22-G22 | I22: Bình thường
A23: TP0020 | B23: Vũ Hoàng Long | C23: Phòng Kinh doanh & Marketing | D23: 12 | E23: 0 | F23: =D23+E23 | G23: =SUMIFS(Theo_doi_don_nghi!H5:H28, Theo_doi_don_nghi!B5:B28, "TP0020", Theo_doi_don_nghi!E5:E28, "Nghỉ phép năm", Theo_doi_don_nghi!K5:K28, "Đã duyệt") | H23: =F23-G23 | I23: Bình thường
A24: TP0021 | B24: Đinh Tuấn Anh | C24: Phòng Kinh doanh & Marketing | D24: 12 | E24: 0 | F24: =D24+E24 | G24: =SUMIFS(Theo_doi_don_nghi!H5:H28, Theo_doi_don_nghi!B5:B28, "TP0021", Theo_doi_don_nghi!E5:E28, "Nghỉ phép năm", Theo_doi_don_nghi!K5:K28, "Đã duyệt") | H24: =F24-G24 | I24: Bình thường
A25: TP0022 | B25: Lý Mỹ Duyên | C25: Phòng Kinh doanh & Marketing | D25: 12 | E25: 0 | F25: =D25+E25 | G25: =SUMIFS(Theo_doi_don_nghi!H5:H28, Theo_doi_don_nghi!B5:B28, "TP0022", Theo_doi_don_nghi!E5:E28, "Nghỉ phép năm", Theo_doi_don_nghi!K5:K28, "Đã duyệt") | H25: =F25-G25 | I25: Bình thường
A26: TP0023 | B26: Nguyễn Mạnh An | C26: Phòng Kinh doanh & Marketing | D26: 0 | E26: 0 | F26: =D26+E26 | G26: =SUMIFS(Theo_doi_don_nghi!H5:H28, Theo_doi_don_nghi!B5:B28, "TP0023", Theo_doi_don_nghi!E5:E28, "Nghỉ phép năm", Theo_doi_don_nghi!K5:K28, "Đã duyệt") | H26: =F26-G26 | I26: Đang thử việc - chưa cấp phép
A27: TP0024 | B27: Dương Thu Trang | C27: Phòng Kinh doanh & Marketing | D27: 12 | E27: 0 | F27: =D27+E27 | G27: =SUMIFS(Theo_doi_don_nghi!H5:H28, Theo_doi_don_nghi!B5:B28, "TP0024", Theo_doi_don_nghi!E5:E28, "Nghỉ phép năm", Theo_doi_don_nghi!K5:K28, "Đã duyệt") | H27: =F27-G27 | I27: Bình thường
A28: TP0025 | B28: Đoàn Khánh Linh | C28: Phòng Kinh doanh & Marketing | D28: 12 | E28: 0 | F28: =D28+E28 | G28: =SUMIFS(Theo_doi_don_nghi!H5:H28, Theo_doi_don_nghi!B5:B28, "TP0025", Theo_doi_don_nghi!E5:E28, "Nghỉ phép năm", Theo_doi_don_nghi!K5:K28, "Đã duyệt") | H28: =F28-G28 | I28: Bình thường
A29: TP0026 | B29: Đỗ Trọng Thắng | C29: Phòng Kỹ thuật & Công nghệ | D29: 12 | E29: 1 | F29: =D29+E29 | G29: =SUMIFS(Theo_doi_don_nghi!H5:H28, Theo_doi_don_nghi!B5:B28, "TP0026", Theo_doi_don_nghi!E5:E28, "Nghỉ phép năm", Theo_doi_don_nghi!K5:K28, "Đã duyệt") | H29: =F29-G29 | I29: Bình thường
A30: TP0027 | B30: Vũ Đình Bách | C30: Phòng Kỹ thuật & Công nghệ | D30: 12 | E30: 0 | F30: =D30+E30 | G30: =SUMIFS(Theo_doi_don_nghi!H5:H28, Theo_doi_don_nghi!B5:B28, "TP0027", Theo_doi_don_nghi!E5:E28, "Nghỉ phép năm", Theo_doi_don_nghi!K5:K28, "Đã duyệt") | H30: =F30-G30 | I30: Bình thường
A31: TP0028 | B31: Nguyễn Công Tuấn | C31: Phòng Kỹ thuật & Công nghệ | D31: 12 | E31: 0 | F31: =D31+E31 | G31: =SUMIFS(Theo_doi_don_nghi!H5:H28, Theo_doi_don_nghi!B5:B28, "TP0028", Theo_doi_don_nghi!E5:E28, "Nghỉ phép năm", Theo_doi_don_nghi!K5:K28, "Đã duyệt") | H31: =F31-G31 | I31: Bình thường
A32: TP0029 | B32: Phạm Văn Hiệp | C32: Phòng Kỹ thuật & Công nghệ | D32: 12 | E32: 0 | F32: =D32+E32 | G32: =SUMIFS(Theo_doi_don_nghi!H5:H28, Theo_doi_don_nghi!B5:B28, "TP0029", Theo_doi_don_nghi!E5:E28, "Nghỉ phép năm", Theo_doi_don_nghi!K5:K28, "Đã duyệt") | H32: =F32-G32 | I32: Bình thường
A33: TP0030 | B33: Trịnh Quang Minh | C33: Phòng Kỹ thuật & Công nghệ | D33: 12 | E33: 0 | F33: =D33+E33 | G33: =SUMIFS(Theo_doi_don_nghi!H5:H28, Theo_doi_don_nghi!B5:B28, "TP0030", Theo_doi_don_nghi!E5:E28, "Nghỉ phép năm", Theo_doi_don_nghi!K5:K28, "Đã duyệt") | H33: =F33-G33 | I33: Bình thường
A34: TP0031 | B34: Hoàng Thế Vinh | C34: Phòng Kỹ thuật & Công nghệ | D34: 12 | E34: 0 | F34: =D34+E34 | G34: =SUMIFS(Theo_doi_don_nghi!H5:H28, Theo_doi_don_nghi!B5:B28, "TP0031", Theo_doi_don_nghi!E5:E28, "Nghỉ phép năm", Theo_doi_don_nghi!K5:K28, "Đã duyệt") | H34: =F34-G34 | I34: Bình thường
A35: TP0032 | B35: Cao Văn Đạt | C35: Phòng Kỹ thuật & Công nghệ | D35: 12 | E35: 0 | F35: =D35+E35 | G35: =SUMIFS(Theo_doi_don_nghi!H5:H28, Theo_doi_don_nghi!B5:B28, "TP0032", Theo_doi_don_nghi!E5:E28, "Nghỉ phép năm", Theo_doi_don_nghi!K5:K28, "Đã duyệt") | H35: =F35-G35 | I35: Bình thường
A36: TP0033 | B36: Nguyễn Khắc Quyền | C36: Xưởng Sản xuất & Vận hành | D36: 12 | E36: 1 | F36: =D36+E36 | G36: =SUMIFS(Theo_doi_don_nghi!H5:H28, Theo_doi_don_nghi!B5:B28, "TP0033", Theo_doi_don_nghi!E5:E28, "Nghỉ phép năm", Theo_doi_don_nghi!K5:K28, "Đã duyệt") | H36: =F36-G36 | I36: Bình thường
A37: TP0034 | B37: Trần Văn Bình | C37: Xưởng Sản xuất & Vận hành | D37: 12 | E37: 0 | F37: =D37+E37 | G37: =SUMIFS(Theo_doi_don_nghi!H5:H28, Theo_doi_don_nghi!B5:B28, "TP0034", Theo_doi_don_nghi!E5:E28, "Nghỉ phép năm", Theo_doi_don_nghi!K5:K28, "Đã duyệt") | H37: =F37-G37 | I37: Bình thường
A38: TP0035 | B38: Đặng Minh Thịnh | C38: Xưởng Sản xuất & Vận hành | D38: 12 | E38: 0 | F38: =D38+E38 | G38: =SUMIFS(Theo_doi_don_nghi!H5:H28, Theo_doi_don_nghi!B5:B28, "TP0035", Theo_doi_don_nghi!E5:E28, "Nghỉ phép năm", Theo_doi_don_nghi!K5:K28, "Đã duyệt") | H38: =F38-G38 | I38: Bình thường
A39: TP0036 | B39: Lê Kim Thơm | C39: Xưởng Sản xuất & Vận hành | D39: 12 | E39: 0 | F39: =D39+E39 | G39: =SUMIFS(Theo_doi_don_nghi!H5:H28, Theo_doi_don_nghi!B5:B28, "TP0036", Theo_doi_don_nghi!E5:E28, "Nghỉ phép năm", Theo_doi_don_nghi!K5:K28, "Đã duyệt") | H39: =F39-G39 | I39: Bình thường
A40: TP0037 | B40: Phạm Hồng Thanh | C40: Xưởng Sản xuất & Vận hành | D40: 12 | E40: 0 | F40: =D40+E40 | G40: =SUMIFS(Theo_doi_don_nghi!H5:H28, Theo_doi_don_nghi!B5:B28, "TP0037", Theo_doi_don_nghi!E5:E28, "Nghỉ phép năm", Theo_doi_don_nghi!K5:K28, "Đã duyệt") | H40: =F40-G40 | I40: Bình thường
A41: TP0038 | B41: Lương Ngọc An | C41: Xưởng Sản xuất & Vận hành | D41: 12 | E41: 0 | F41: =D41+E41 | G41: =SUMIFS(Theo_doi_don_nghi!H5:H28, Theo_doi_don_nghi!B5:B28, "TP0038", Theo_doi_don_nghi!E5:E28, "Nghỉ phép năm", Theo_doi_don_nghi!K5:K28, "Đã duyệt") | H41: =F41-G41 | I41: Bình thường
...
