Workbook

Sheet Bang_luong_T09_2026
A1: BẢNG THANH TOÁN TIỀN LƯƠNG THÁNG 09/2026 - CÔNG TY A
A2: Đơn vị tính: VNĐ | Kỳ thanh toán: Tháng 09/2026 (Quyết toán Quý 3/2026) | Quy định: Nghị quyết 954 & Luật BHXH
A4: Mã NV | B4: Họ và tên | C4: Phòng ban | D4: Chức danh | E4: Mức lương HĐ | F4: Ngày công | G4: Lương thời gian | H4: Phụ cấp TN | I4: Phụ cấp ăn trưa | J4: Tiền làm thêm OT | K4: Thưởng hiệu quả | L4: Tổng thu nhập | M4: BHXH,YT,TN (10.5%) | N4: Thuế TNCN | O4: Thực lĩnh | P4: Ghi chú
A5: TP0001 | B5: Phạm Thái Hùng | C5: Ban Giám đốc | D5: Tổng Giám đốc | E5: 35000000 | F5: 26 | G5: =ROUND(E5/26*F5, 0) | H5: 15000000 | I5: 730000 | J5: 0 | K5: 2000000 | L5: =SUM(G5:K5) | M5: 3675000 | N5: 4981250 | O5: =L5-M5-N5
A6: TP0002 | B6: Nguyễn Minh Tuấn | C6: Ban Giám đốc | D6: Phó Tổng Giám đốc | E6: 35000000 | F6: 26 | G6: =ROUND(E6/26*F6, 0) | H6: 10000000 | I6: 730000 | J6: 0 | K6: 2000000 | L6: =SUM(G6:K6) | M6: 3675000 | N6: 3055000 | O6: =L6-M6-N6
A7: TP0003 | B7: Trần Mai Phương | C7: Ban Giám đốc | D7: Trợ lý Ban Giám đốc | E7: 12000000 | F7: 26 | G7: =ROUND(E7/26*F7, 0) | H7: 3000000 | I7: 730000 | J7: 0 | K7: 2000000 | L7: =SUM(G7:K7) | M7: 1260000 | N7: 237000 | O7: =L7-M7-N7
A8: TP0004 | B8: Hà Quang Dũng | C8: Phòng Hành chính - Nhân sự | D8: Trưởng phòng Hành chính - Nhân sự | E8: 22000000 | F8: 26 | G8: =ROUND(E8/26*F8, 0) | H8: 5000000 | I8: 730000 | J8: 0 | K8: 2000000 | L8: =SUM(G8:K8) | M8: 2310000 | N8: 943500 | O8: =L8-M8-N8
A9: TP0005 | B9: Đỗ Thị Quỳnh Nga | C9: Phòng Hành chính - Nhân sự | D9: Chuyên viên Tuyển dụng & Đào tạo | E9: 12000000 | F9: 26 | G9: =ROUND(E9/26*F9, 0) | H9: 1500000 | I9: 730000 | J9: 0 | K9: 800000 | L9: =SUM(G9:K9) | M9: 1260000 | N9: 0 | O9: =L9-M9-N9
A10: TP0006 | B10: Vũ Phương Linh | C10: Phòng Hành chính - Nhân sự | D10: Chuyên viên C&B (Tiền lương - Phúc lợi) | E10: 12000000 | F10: 26 | G10: =ROUND(E10/26*F10, 0) | H10: 1500000 | I10: 730000 | J10: 0 | K10: 800000 | L10: =SUM(G10:K10) | M10: 1260000 | N10: 102000 | O10: =L10-M10-N10
A11: TP0007 | B11: Nguyễn Ngọc Bích | C11: Phòng Hành chính - Nhân sự | D11: Nhân viên Hành chính - Lễ tân | E11: 8500000 | F11: 26 | G11: =ROUND(E11/26*F11, 0) | H11: 500000 | I11: 730000 | J11: 0 | K11: 800000 | L11: =SUM(G11:K11) | M11: 892500 | N11: 0 | O11: =L11-M11-N11
A12: TP0008 | B12: Hoàng Thu Thảo | C12: Phòng Hành chính - Nhân sự | D12: Nhân viên Hành chính - Lễ tân | E12: 7225000 | F12: 26 | G12: =ROUND(E12/26*F12, 0) | H12: 0 | I12: 730000 | J12: 0 | K12: 500000 | L12: =SUM(G12:K12) | M12: 0 | N12: 0 | O12: =L12-M12-N12 | P12: Lương thử việc tháng thứ 2 (kèm thưởng động viên)
A13: TP0009 | B13: Lê Thu Lan | C13: Phòng Tài chính - Kế toán | D13: Kế toán trưởng | E13: 22000000 | F13: 26 | G13: =ROUND(E13/26*F13, 0) | H13: 6000000 | I13: 730000 | J13: 0 | K13: 800000 | L13: =SUM(G13:K13) | M13: 2310000 | N13: 419000 | O13: =L13-M13-N13
A14: TP0010 | B14: Nguyễn Bích Thủy | C14: Phòng Tài chính - Kế toán | D14: Kế toán tổng hợp | E14: 8500000 | F14: 26 | G14: =ROUND(E14/26*F14, 0) | H14: 2000000 | I14: 730000 | J14: 0 | K14: 800000 | L14: =SUM(G14:K14) | M14: 892500 | N14: 0 | O14: =L14-M14-N14
A15: TP0011 | B15: Trần Thùy Dương | C15: Phòng Tài chính - Kế toán | D15: Kế toán thanh toán & Công nợ | E15: 8500000 | F15: 26 | G15: =ROUND(E15/26*F15, 0) | H15: 1000000 | I15: 730000 | J15: 0 | K15: 800000 | L15: =SUM(G15:K15) | M15: 892500 | N15: 0 | O15: =L15-M15-N15
A16: TP0012 | B16: Phan Thanh Hoa | C16: Phòng Tài chính - Kế toán | D16: Kế toán thanh toán & Công nợ | E16: 8500000 | F16: 26 | G16: =ROUND(E16/26*F16, 0) | H16: 1000000 | I16: 730000 | J16: 0 | K16: 800000 | L16: =SUM(G16:K16) | M16: 892500 | N16: 0 | O16: =L16-M16-N16
A17: TP0013 | B17: Bùi Văn Khôi | C17: Phòng Tài chính - Kế toán | D17: Kế toán kho & Vật tư | E17: 8500000 | F17: 26 | G17: =ROUND(E17/26*F17, 0) | H17: 500000 | I17: 730000 | J17: 0 | K17: 800000 | L17: =SUM(G17:K17) | M17: 892500 | N17: 0 | O17: =L17-M17-N17
A18: TP0014 | B18: Nguyễn Văn Hùng | C18: Phòng Kinh doanh & Marketing | D18: Trưởng phòng Kinh doanh | E18: 22000000 | F18: 26 | G18: =ROUND(E18/26*F18, 0) | H18: 6000000 | I18: 730000 | J18: 0 | K18: 4500000 | L18: =SUM(G18:K18) | M18: 2310000 | N18: 808500 | O18: =L18-M18-N18
A19: TP0015 | B19: Nguyễn Việt Kiên | C19: Phòng Kinh doanh & Marketing | D19: Phó phòng Kinh doanh | E19: 16000000 | F19: 26 | G19: =ROUND(E19/26*F19, 0) | H19: 3500000 | I19: 730000 | J19: 692308 | K19: 3200000 | L19: =SUM(G19:K19) | M19: 1680000 | N19: 381231 | O19: =L19-M19-N19
A20: TP0016 | B20: Đặng Minh Nam | C20: Phòng Kinh doanh & Marketing | D20: Chuyên viên Digital Marketing | E20: 12000000 | F20: 26 | G20: =ROUND(E20/26*F20, 0) | H20: 1500000 | I20: 730000 | J20: 0 | K20: 3200000 | L20: =SUM(G20:K20) | M20: 1260000 | N20: 222000 | O20: =L20-M20-N20
A21: TP0017 | B21: Lê Diệu Linh | C21: Phòng Kinh doanh & Marketing | D21: Chuyên viên Digital Marketing | E21: 12000000 | F21: 26 | G21: =ROUND(E21/26*F21, 0) | H21: 1500000 | I21: 730000 | J21: 0 | K21: 3200000 | L21: =SUM(G21:K21) | M21: 1260000 | N21: 222000 | O21: =L21-M21-N21
A22: TP0018 | B22: Phạm Quốc Bảo | C22: Phòng Kinh doanh & Marketing | D22: Nhân viên Kinh doanh (Sales Rep) | E22: 8500000 | F22: 26 | G22: =ROUND(E22/26*F22, 0) | H22: 1000000 | I22: 730000 | J22: 0 | K22: 3200000 | L22: =SUM(G22:K22) | M22: 892500 | N22: 0 | O22: =L22-M22-N22
A23: TP0019 | B23: Trần Hải Yến | C23: Phòng Kinh doanh & Marketing | D23: Nhân viên Kinh doanh (Sales Rep) | E23: 8500000 | F23: 26 | G23: =ROUND(E23/26*F23, 0) | H23: 1000000 | I23: 730000 | J23: 0 | K23: 3200000 | L23: =SUM(G23:K23) | M23: 892500 | N23: 0 | O23: =L23-M23-N23
A24: TP0020 | B24: Vũ Hoàng Long | C24: Phòng Kinh doanh & Marketing | D24: Nhân viên Kinh doanh (Sales Rep) | E24: 8500000 | F24: 26 | G24: =ROUND(E24/26*F24, 0) | H24: 1000000 | I24: 730000 | J24: 0 | K24: 3200000 | L24: =SUM(G24:K24) | M24: 892500 | N24: 40375 | O24: =L24-M24-N24
... A26: TP0022 | B26: Lý Mỹ Duyên | C26: Phòng Kinh doanh & Marketing | D26: Nhân viên Kinh doanh (Sales Rep) | E26: 8500000 | F26: 24 | G26: =ROUND(E26/26*F26, 0) | H26: 1000000 | I26: 730000 | J26: 0 | K26: 3200000 | L26: =SUM(G26:K26) | M26: 892500 | N26: 7683 | O26: =L26-M26-N26
A27: TP0023 | B27: Nguyễn Mạnh An | C27: Phòng Kinh doanh & Marketing | D27: Nhân viên Kinh doanh (Sales Rep) | E27: 7225000 | F27: 26 | G27: =ROUND(E27/26*F27, 0) | H27: 0 | I27: 730000 | J27: 0 | K27: 500000 | L27: =SUM(G27:K27) | M27: 0 | N27: 0 | O27: =L27-M27-N27 | P27: Lương thử việc tháng thứ 2 (kèm thưởng động viên)
A28: TP0024 | B28: Dương Thu Trang | C28: Phòng Kinh doanh & Marketing | D28: Nhân viên Chăm sóc khách hàng | E28: 8500000 | F28: 26 | G28: =ROUND(E28/26*F28, 0) | H28: 800000 | I28: 730000 | J28: 0 | K28: 3200000 | L28: =SUM(G28:K28) | M28: 892500 | N28: 0 | O28: =L28-M28-N28
A29: TP0025 | B29: Đoàn Khánh Linh | C29: Phòng Kinh doanh & Marketing | D29: Nhân viên Chăm sóc khách hàng | E29: 8500000 | F29: 26 | G29: =ROUND(E29/26*F29, 0) | H29: 800000 | I29: 730000 | J29: 0 | K29: 3200000 | L29: =SUM(G29:K29) | M29: 892500 | N29: 30375 | O29: =L29-M29-N29
A30: TP0026 | B30: Đỗ Trọng Thắng | C30: Phòng Kỹ thuật & Công nghệ | D30: Trưởng phòng Kỹ thuật | E30: 22000000 | F30: 26 | G30: =ROUND(E30/26*F30, 0) | H30: 6000000 | I30: 730000 | J30: 1586538 | K30: 2000000 | L30: =SUM(G30:K30) | M30: 2310000 | N30: 697654 | O30: =L30-M30-N30
A31: TP0027 | B31: Vũ Đình Bách | C31: Phòng Kỹ thuật & Công nghệ | D31: Kỹ sư Hệ thống / IT Support | E31: 12000000 | F31: 26 | G31: =ROUND(E31/26*F31, 0) | H31: 2000000 | I31: 730000 | J31: 0 | K31: 800000 | L31: =SUM(G31:K31) | M31: 1260000 | N31: 0 | O31: =L31-M31-N31
A32: TP0028 | B32: Nguyễn Công Tuấn | C32: Phòng Kỹ thuật & Công nghệ | D32: Kỹ sư Hệ thống / IT Support | E32: 12000000 | F32: 26 | G32: =ROUND(E32/26*F32, 0) | H32: 2000000 | I32: 730000 | J32: 865385 | K32: 800000 | L32: =SUM(G32:K32) | M32: 1260000 | N32: 170269 | O32: =L32-M32-N32
A33: TP0029 | B33: Phạm Văn Hiệp | C33: Phòng Kỹ thuật & Công nghệ | D33: Kỹ sư Bảo trì & Cơ điện | E33: 12000000 | F33: 26 | G33: =ROUND(E33/26*F33, 0) | H33: 2000000 | I33: 730000 | J33: 0 | K33: 800000 | L33: =SUM(G33:K33) | M33: 1260000 | N33: 0 | O33: =L33-M33-N33
A34: TP0030 | B34: Trịnh Quang Minh | C34: Phòng Kỹ thuật & Công nghệ | D34: Kỹ sư Bảo trì & Cơ điện | E34: 12000000 | F34: 26 | G34: =ROUND(E34/26*F34, 0) | H34: 2000000 | I34: 730000 | J34: 865385 | K34: 800000 | L34: =SUM(G34:K34) | M34: 1260000 | N34: 170269 | O34: =L34-M34-N34
A35: TP0031 | B35: Hoàng Thế Vinh | C35: Phòng Kỹ thuật & Công nghệ | D35: Nhân viên Kỹ thuật | E35: 8500000 | F35: 26 | G35: =ROUND(E35/26*F35, 0) | H35: 1000000 | I35: 730000 | J35: 0 | K35: 800000 | L35: =SUM(G35:K35) | M35: 892500 | N35: 0 | O35: =L35-M35-N35
A36: TP0032 | B36: Cao Văn Đạt | C36: Phòng Kỹ thuật & Công nghệ | D36: Nhân viên Kỹ thuật | E36: 8500000 | F36: 26 | G36: =ROUND(E36/26*F36, 0) | H36: 1000000 | I36: 730000 | J36: 612981 | K36: 800000 | L36: =SUM(G36:K36) | M36: 892500 | N36: 0 | O36: =L36-M36-N36
A37: TP0033 | B37: Nguyễn Khắc Quyền | C37: Xưởng Sản xuất & Vận hành | D37: Quản đốc Xưởng sản xuất | E37: 22000000 | F37: 26 | G37: =ROUND(E37/26*F37, 0) | H37: 6000000 | I37: 730000 | J37: 2750000 | K37: 1800000 | L37: =SUM(G37:K37) | M37: 2310000 | N37: 816000 | O37: =L37-M37-N37
A38: TP0034 | B38: Trần Văn Bình | C38: Xưởng Sản xuất & Vận hành | D38: Tổ trưởng Sản xuất | E38: 12000000 | F38: 26 | G38: =ROUND(E38/26*F38, 0) | H38: 2500000 | I38: 730000 | J38: 0 | K38: 800000 | L38: =SUM(G38:K38) | M38: 1260000 | N38: 0 | O38: =L38-M38-N38
A39: TP0035 | B39: Đặng Minh Thịnh | C39: Xưởng Sản xuất & Vận hành | D39: Tổ trưởng Sản xuất | E39: 12000000 | F39: 26 | G39: =ROUND(E39/26*F39, 0) | H39: 2500000 | I39: 730000 | J39: 1500000 | K39: 1800000 | L39: =SUM(G39:K39) | M39: 1260000 | N39: 57000 | O39: =L39-M39-N39
... A49: TP0045 | B49: Lê Văn Tuấn | C49: Xưởng Sản xuất & Vận hành | D49: Công nhân sản xuất / Đóng gói | E49: 6500000 | F49: 26 | G49: =ROUND(E49/26*F49, 0) | H49: 0 | I49: 730000 | J49: 812500 | K49: 1800000 | L49: =SUM(G49:K49) | M49: 682500 | N49: 0 | O49: =L49-M49-N49
A50: TP0046 | B50: Nguyễn Thị Sen | C50: Xưởng Sản xuất & Vận hành | D50: Công nhân sản xuất / Đóng gói | E50: 6500000 | F50: 0 | G50: 0 | H50: 0 | I50: 0 | J50: 0 | K50: 0 | L50: 0 | M50: 0 | N50: 0 | O50: 0 | P50: Nghỉ thai sản (BHXH chi trả)
A51: TP0047 | B51: Đinh Trọng Hưng | C51: Xưởng Sản xuất & Vận hành | D51: Công nhân sản xuất / Đóng gói | E51: 6500000 | F51: 26 | G51: =ROUND(E51/26*F51, 0) | H51: 0 | I51: 730000 | J51: 812500 | K51: 1800000 | L51: =SUM(G51:K51) | M51: 682500 | N51: 0 | O51: =L51-M51-N51
...

Sheet Quy_luong_phong_ban
A1: BÁO CÁO TỔNG HỢP QUỸ LƯƠNG THEO PHÒNG BAN - THÁNG 09/2026
A3: STT | B3: Phòng ban | C3: Số nhân sự | D3: Tổng thu nhập (VNĐ) | E3: Trừ BHXH,YT,TN (VNĐ) | F3: Thuế TNCN (VNĐ) | G3: Thực lĩnh chi trả (VNĐ) | H3: Tỷ trọng (%)
A4: 1 | B4: Ban Giám đốc | C4: =COUNTIF(Bang_luong_T09_2026!C5:C54, "Ban Giám đốc") | D4: =SUMIF(Bang_luong_T09_2026!C5:C54, "Ban Giám đốc", Bang_luong_T09_2026!L5:L54) | E4: =SUMIF(Bang_luong_T09_2026!C5:C54, "Ban Giám đốc", Bang_luong_T09_2026!M5:M54) | F4: =SUMIF(Bang_luong_T09_2026!C5:C54, "Ban Giám đốc", Bang_luong_T09_2026!N5:N54) | G4: =SUMIF(Bang_luong_T09_2026!C5:C54, "Ban Giám đốc", Bang_luong_T09_2026!O5:O54) | H4: =G4/G10
A5: 2 | B5: Phòng Hành chính - Nhân sự | C5: =COUNTIF(Bang_luong_T09_2026!C5:C54, "Phòng Hành chính - Nhân sự") | D5: =SUMIF(Bang_luong_T09_2026!C5:C54, "Phòng Hành chính - Nhân sự", Bang_luong_T09_2026!L5:L54) | E5: =SUMIF(Bang_luong_T09_2026!C5:C54, "Phòng Hành chính - Nhân sự", Bang_luong_T09_2026!M5:M54) | F5: =SUMIF(Bang_luong_T09_2026!C5:C54, "Phòng Hành chính - Nhân sự", Bang_luong_T09_2026!N5:N54) | G5: =SUMIF(Bang_luong_T09_2026!C5:C54, "Phòng Hành chính - Nhân sự", Bang_luong_T09_2026!O5:O54) | H5: =G5/G10
A6: 3 | B6: Phòng Tài chính - Kế toán | C6: =COUNTIF(Bang_luong_T09_2026!C5:C54, "Phòng Tài chính - Kế toán") | D6: =SUMIF(Bang_luong_T09_2026!C5:C54, "Phòng Tài chính - Kế toán", Bang_luong_T09_2026!L5:L54) | E6: =SUMIF(Bang_luong_T09_2026!C5:C54, "Phòng Tài chính - Kế toán", Bang_luong_T09_2026!M5:M54) | F6: =SUMIF(Bang_luong_T09_2026!C5:C54, "Phòng Tài chính - Kế toán", Bang_luong_T09_2026!N5:N54) | G6: =SUMIF(Bang_luong_T09_2026!C5:C54, "Phòng Tài chính - Kế toán", Bang_luong_T09_2026!O5:O54) | H6: =G6/G10
A7: 4 | B7: Phòng Kinh doanh & Marketing | C7: =COUNTIF(Bang_luong_T09_2026!C5:C54, "Phòng Kinh doanh & Marketing") | D7: =SUMIF(Bang_luong_T09_2026!C5:C54, "Phòng Kinh doanh & Marketing", Bang_luong_T09_2026!L5:L54) | E7: =SUMIF(Bang_luong_T09_2026!C5:C54, "Phòng Kinh doanh & Marketing", Bang_luong_T09_2026!M5:M54) | F7: =SUMIF(Bang_luong_T09_2026!C5:C54, "Phòng Kinh doanh & Marketing", Bang_luong_T09_2026!N5:N54) | G7: =SUMIF(Bang_luong_T09_2026!C5:C54, "Phòng Kinh doanh & Marketing", Bang_luong_T09_2026!O5:O54) | H7: =G7/G10
A8: 5 | B8: Phòng Kỹ thuật & Công nghệ | C8: =COUNTIF(Bang_luong_T09_2026!C5:C54, "Phòng Kỹ thuật & Công nghệ") | D8: =SUMIF(Bang_luong_T09_2026!C5:C54, "Phòng Kỹ thuật & Công nghệ", Bang_luong_T09_2026!L5:L54) | E8: =SUMIF(Bang_luong_T09_2026!C5:C54, "Phòng Kỹ thuật & Công nghệ", Bang_luong_T09_2026!M5:M54) | F8: =SUMIF(Bang_luong_T09_2026!C5:C54, "Phòng Kỹ thuật & Công nghệ", Bang_luong_T09_2026!N5:N54) | G8: =SUMIF(Bang_luong_T09_2026!C5:C54, "Phòng Kỹ thuật & Công nghệ", Bang_luong_T09_2026!O5:O54) | H8: =G8/G10
A9: 6 | B9: Xưởng Sản xuất & Vận hành | C9: =COUNTIF(Bang_luong_T09_2026!C5:C54, "Xưởng Sản xuất & Vận hành") | D9: =SUMIF(Bang_luong_T09_2026!C5:C54, "Xưởng Sản xuất & Vận hành", Bang_luong_T09_2026!L5:L54) | E9: =SUMIF(Bang_luong_T09_2026!C5:C54, "Xưởng Sản xuất & Vận hành", Bang_luong_T09_2026!M5:M54) | F9: =SUMIF(Bang_luong_T09_2026!C5:C54, "Xưởng Sản xuất & Vận hành", Bang_luong_T09_2026!N5:N54) | G9: =SUMIF(Bang_luong_T09_2026!C5:C54, "Xưởng Sản xuất & Vận hành", Bang_luong_T09_2026!O5:O54) | H9: =G9/G10
B10: TỔNG TOÀN CÔNG TY | C10: =SUM(C4:C9) | D10: =SUM(D4:D9) | E10: =SUM(E4:E9) | F10: =SUM(F4:F9) | G10: =SUM(G4:G9) | H10: =SUM(H4:H9)

Sheet Bien_dong_quy_luong_Q3
A1: BÁO CÁO TỔNG KẾT & SO SÁNH QUỸ LƯƠNG QUÝ 3/2026
A3: Kỳ lương | B3: Tổng nhân sự tính lương | C3: Tổng quỹ thu nhập (VNĐ) | D3: Tổng trích nộp BHXH (VNĐ) | E3: Tổng thuế TNCN (VNĐ) | F3: Tổng lương thực lĩnh (VNĐ) | G3: Tăng trưởng so tháng trước
A4: Tháng 07/2026 | B4: 46 | C4: 685350000 | D4: 48300000 | E4: 18550000 | F4: 618500000 | G4: -
A5: Tháng 08/2026 | B5: 49 | C5: 725450000 | D5: 48300000 | E5: 20420000 | F5: 656730000 | G5: +6.18%
A6: Tháng 09/2026 | B6: 49 | C6: =L55 | D6: =M55 | E6: =N55 | F6: =O55 | G6: =(F6-F5)/F5
